Workbook

Sheet Experiments
A1: Trial ID | B1: Date | C1: Task ID | D1: Scene Layout | E1: Scenario ID | F1: Scenario | G1: Level | H1: Modifiers | I1: Command Used | J1: Intended Target | K1: Intended Destination | L1: User Intent understood correctly? | M1: Object Detected? | N1: Correct Object Selected? | O1: Grasp Success? | P1: Action Executed Correctly? | Q1: Full Task Success? | R1: Interaction Time (s) | S1: Total Time (s) | T1: Failure Category / Notes | U1: Started by | V1: Understood by | W1: GraspGen in background? | X1: Execution plan | Y1: Plan checked in background? | Z1: Grasp executed | AA1: Command → object handed over (s) | AB1: Waiting for your answers (s) | AC1: Robot time (s) | AD1: Times | AE1: VLA task | AF1: VLA outcome | AG1: Folder | AH1: Viewer | AI1: Video
A2: 086 | B2: 2026-09-28 | D2: Layout A | E2: S1 | F2: S1: Available objects — no physical action | G2: L1 single-step, explicit | I2: What do you see on the table? | U2: voice | AD2: final | AG2: trial_086_LA_S1 | AI2: video
A3: 087 | B3: 2026-09-28 | D3: Layout A | E3: S2 | F3: S2: Object NOT in scene ('give me the book') | G3: L1 single-step, explicit | I3: Give me the book, Morty. | J3: tape_dispenser | K3: — | U3: voice | AD3: final | AG3: trial_087_LA_S2 | AI3: video
A4: 088 | B4: 2026-09-28 | D4: Layout A | E4: S3 | F4: S3: One of a kind among others — ask for it | G4: L1 single-step, explicit | I4: Grasp for me the tape dispenser. | J4: tape_dispenser | K4: drop_right | L4: yes | M4: yes | N4: yes | O4: yes | P4: yes | Q4: yes | R4: 5.21 | S4: 45.08 | U4: voice | V4: instant rule | W4: yes | X4: curve | Y4: yes | Z4: 1 of 26 | AA4: 32.542 | AB4: 21.106 | AC4: 23.974 | AD4: final | AE4: pick up the tape dispenser | AF4: success | AG4: trial_088_LA_S3 | AH4: viewer | AI4: video
A5: 089 | B5: 2026-09-28 | D5: Layout A | E5: S4 | F5: S4: Two same kind — clarify by words (left/right/colour) | G5: L1 single-step, explicit | I5: Grasp for me the vitamin tube. | J5: vitamin_c | K5: drop_left | L5: yes | M5: yes | N5: yes | O5: yes | P5: yes | Q5: yes | R5: 11.901 | S5: 49.555 | U5: voice | V5: instant rule | W5: yes | X5: curve | Y5: yes | Z5: 1 of 11 | AA5: 37.421 | AB5: 22.598 | AC5: 26.957 | AD5: final | AE5: pick up the leftmost vitamin tube | AF5: success | AG5: trial_089_LA_S4 | AH5: viewer | AI5: video
A6: 090 | B6: 2026-09-28 | D6: Layout A | E6: S5 | F6: S5: Two same kind — clarify by pointing | G6: L1 single-step, explicit | I6: Grasp for me the vitamin tube. | J6: vitamin_B12 | K6: drop_right | L6: yes | M6: yes | N6: yes | O6: yes | P6: yes | Q6: yes | R6: 10.304 | S6: 49.439 | U6: voice | V6: instant rule | W6: yes | X6: curve | Y6: yes | Z6: 3 of 24 | AA6: 37.947 | AB6: 19.917 | AC6: 29.522 | AD6: final | AE6: pick up the vitamin tube | AF6: success | AG6: trial_090_LA_S5 | AH6: viewer | AI6: video
A7: 091 | B7: 2026-09-28 | D7: Layout A | E7: S6 | F7: S6: Pointing only (with confirmation) | G7: L1 single-step, explicit | H7: M1 | I7: Drop it on the right side. | J7: tape_dispenser | K7: drop_right | L7: yes | M7: yes | N7: yes | O7: yes | P7: yes | Q7: yes | R7: 0.511 | S7: 47.072 | U7: pointing/click | W7: yes | X7: curve | Y7: yes | Z7: 1 of 25 | AA7: 39.692 | AB7: 28.371 | AC7: 18.701 | AD7: final | AE7: pick up the tape dispenser | AF7: success | AG7: trial_091_LA_S6 | AH7: viewer | AI7: video
A8: 092 | B8: 2026-09-28 | D8: Layout A | E8: S1 | F8: S1: Available objects — no physical action | G8: L1 single-step, explicit | I8: Morty, could you please tell me which objects you can pick up right now? | J8: — | K8: — | U8: voice | AD8: final | AG8: trial_092_LA_S1 | AI8: video
A9: 093 | B9: 2026-09-28 | D9: Layout A | E9: S2 | F9: S2: Object NOT in scene ('give me the book') | G9: L1 single-step, explicit | I9: Could you please bring me my phone? | J9: phone | K9: — | L9: yes | M9: yes | U9: voice | AD9: final | AG9: trial_093_LA_S2 | AI9: video
A10: 095 | B10: 2026-09-28 | D10: Layout A | E10: S3 | F10: S3: One of a kind among others — ask for it | G10: L1 single-step, explicit | I10: Could you slowly bring me the small bottle, please? | J10: small_bottle | K10: drop_left | L10: yes | M10: yes | N10: yes | O10: yes | P10: yes | Q10: yes | R10: 4.194 | S10: 39.212 | U10: voice | V10: language model | W10: yes | X10: curve | Y10: yes | Z10: 3 of 18 | AA10: 29.932 | AB10: 20.712 | AC10: 18.5 | AD10: final | AE10: pick up the small bottle | AF10: success | AG10: trial_095_LA_S3 | AH10: viewer | AI10: video
A11: 097 | B11: 2026-09-28 | D11: Layout A | E11: S5 | F11: S5: Two same kind — clarify by pointing | G11: L1 single-step, explicit | H11: M1 | I11: Get me the vitamin tube. | J11: vitamin_c | K11: drop_right | L11: yes | M11: yes | N11: yes | O11: yes | P11: yes | Q11: yes | R11: 12.254 | S11: 44.393 | U11: voice | V11: language model | W11: yes | X11: curve | Y11: no | Z11: 1 of 24 | AA11: 39.29 | AB11: 16.688 | AC11: 27.705 | AD11: final | AE11: pick up the vitamin tube | AF11: success | AG11: trial_097_LA_S5 | AH11: viewer | AI11: video
A12: 096 | B12: 2026-09-28 | D12: Layout A | E12: S4 | F12: S4: Two same kind — clarify by words (left/right/colour) | G12: L1 single-step, explicit | I12: Grasp for me the vitamin tube. | J12: vitamin_B12 | K12: home | L12: yes | M12: yes | N12: yes | O12: yes | P12: yes | Q12: yes | R12: 12.069 | S12: 40.616 | U12: voice | V12: instant rule | W12: yes | X12: curve | Y12: yes | Z12: 2 of 25 | AA12: 38.474 | AB12: 14.79 | AC12: 25.826 | AD12: final | AE12: pick up the rightmost vitamin tube | AF12: success | AG12: trial_096_LA_S4 | AH12: viewer | AI12: video
A13: 099 | B13: 2026-09-28 | D13: Layout A | E13: S3 | F13: S3: One of a kind among others — ask for it | G13: L1 single-step, explicit | I13: Can you give me the small bottle? | J13: small_bottle | K13: — | R13: 2.966 | S13: 42.285 | U13: voice | V13: instant rule | W13: yes | X13: curve | Y13: yes | Z13: 2 of 13 | AA13: 25.188 | AB13: 21.286 | AC13: 20.999 | AD13: final | AE13: pick up the small bottle | AF13: success | AG13: trial_099_LA_S3 | AH13: viewer | AI13: video
A14: 100 | B14: 2026-09-28 | D14: Layout A | E14: S3 | F14: S3: One of a kind among others — ask for it | G14: L1 single-step, explicit | I14: I need a tape dispenser. | J14: tape_dispenser | K14: home | L14: yes | M14: yes | N14: yes | O14: yes | P14: yes | Q14: yes | R14: 6.371 | S14: 33.524 | U14: voice | V14: language model | W14: yes | X14: curve | Y14: yes | Z14: 5 of 17 | AA14: 33.765 | AB14: 15.565 | AC14: 17.959 | AD14: final | AE14: pick up the tape dispenser | AF14: success | AG14: trial_100_LA_S3 | AH14: viewer | AI14: video
A15: 101 | B15: 2026-09-28 | D15: Layout A | E15: S4 | F15: S4: Two same kind — clarify by words (left/right/colour) | G15: L1 single-step, explicit | H15: M3 | I15: Give me the vitamin tube. | J15: vitamin_c | K15: drop_right | L15: yes | M15: yes | N15: yes | O15: yes | P15: yes | Q15: yes | R15: 21.338 | S15: 81.227 | U15: voice | V15: instant rule | W15: yes | X15: curve | Y15: yes | Z15: 1 of 16 | AA15: 62.726 | AB15: 34.836 | AC15: 46.391 | AD15: final | AE15: pick up the leftmost vitamin tube | AF15: success | AG15: trial_101_LA_S4 | AH15: viewer | AI15: video
A16: 105 | B16: 2026-09-28 | D16: Layout A | E16: S1 | F16: S1: Available objects — no physical action | G16: L1 single-step, explicit | I16: Tell me Morty, what kind of object are you seeing right now? | J16: — | K16: — | U16: voice | AD16: final | AG16: trial_105_LA_S1 | AI16: video
A17: 107 | B17: 2026-09-28 | D17: Layout A | E17: S2 | F17: S2: Object NOT in scene ('give me the book') | G17: L1 single-step, explicit | I17: Give me the toy faucet. | J17: toy_faucet | K17: — | U17: voice | V17: instant rule | AD17: final | AG17: trial_107_LA_S2 | AI17: video
A18: 108 | B18: 2026-09-28 | D18: Layout A | E18: S3 | F18: S3: One of a kind among others — ask for it | G18: L1 single-step, explicit | H18: M1 | I18: Can you give me the white bottle | J18: small_bottle | K18: home | L18: yes | M18: yes | N18: yes | O18: yes | P18: yes | Q18: yes | R18: 3.759 | S18: 28.08 | U18: voice | V18: language model | W18: yes | X18: curve | Y18: yes | Z18: 4 of 19 | AA18: 25.893 | AB18: 9.713 | AC18: 18.367 | AD18: final | AG18: trial_108_LA_S3 | AI18: video
A19: 109 | B19: 2026-09-28 | D19: Layout A | E19: S4 | F19: S4: Two same kind — clarify by words (left/right/colour) | G19: L1 single-step, explicit | I19: Grasp for me the vitamin tube. | J19: vitamin_c | K19: home | L19: yes | M19: yes | N19: yes | O19: yes | P19: yes | Q19: yes | R19: 12.288 | S19: 41.687 | U19: voice | V19: language model | W19: yes | X19: curve | Y19: yes | Z19: 1 of 23 | AA19: 39.452 | AB19: 14.872 | AC19: 26.815 | AD19: final | AG19: trial_109_LA_S4 | AI19: video
A20: 110 | B20: 2026-09-28 | D20: Layout A | E20: S5 | F20: S5: Two same kind — clarify by pointing | G20: L1 single-step, explicit | H20: M1 | I20: Grasp for me the vitamin tube. | J20: vitamin_c | K20: drop_right | L20: yes | M20: yes | N20: yes | O20: yes | P20: yes | Q20: yes | R20: 26.027 | S20: 62.865 | T20: Intent first misunderstood because of an incorrect voice transcription ("Yes, say a long one." — Morty told a story); understood after that ("No.", "The yellow one."). | U20: voice | V20: instant rule | W20: yes | X20: curve | Y20: yes | Z20: 1 of 15 | AA20: 56.328 | AB20: 32.296 | AC20: 30.569 | AD20: final | AG20: trial_110_LA_S5 | AI20: video
A21: 111 | B21: 2026-09-28 | D21: Layout A | E21: S6 | F21: S6: Pointing only (with confirmation) | G21: L1 single-step, explicit | H21: M1 | I21: Yes, grasp it. | J21: tape_dispenser | K21: drop_right | L21: yes | M21: yes | N21: yes | O21: yes | P21: yes | Q21: yes | R21: 1.465 | S21: 28.187 | U21: voice | V21: instant rule | W21: yes | X21: curve | Y21: yes | Z21: 1 of 13 | AA21: 21.35 | AB21: 20.118 | AC21: 8.069 | AD21: final | AG21: trial_111_LA_S6 | AI21: video
A22: 112 | B22: 2026-09-28 | D22: Layout A | E22: S7 | F22: S7: Moving without grasping | G22: L1 single-step, explicit | H22: M1 | I22: Look at the left, then the right, then go back home. | J22: — | K22: — | R22: 3.814 | U22: voice | V22: language model | AD22: final | AG22: trial_112_LA_S7 | AI22: video
A23: 114 | B23: 2026-09-29 | D23: Layout A | E23: S7 | F23: S7: Moving without grasping | G23: L1 single-step, explicit | H23: M1 | I23: Morty, look at the right side first, then go home. | J23: — | K23: — | L23: yes | Q23: yes | R23: 9.284 | U23: voice | V23: language model | AD23: final | AE23: look to the right | AF23: success | AG23: trial_114_LA_S7 | AH23: viewer | AI23: video
A24: 113 | B24: 2026-09-29 | D24: Layout A | E24: S7 | F24: S7: Moving without grasping | G24: L1 single-step, explicit | H24: M1 | I24: Morty, how are you? Can you look at the left side, then go to the drop right side. | J24: — | K24: — | L24: yes | Q24: yes | R24: 5.12 | U24: voice | V24: language model | AD24: final | AE24: look to the left | AF24: success | AG24: trial_113_LA_S7 | AH24: viewer | AI24: video
A25: 115 | B25: 2026-09-29 | D25: Layout A | E25: S6 | F25: S6: Pointing only (with confirmation) | G25: L1 single-step, explicit | I25: Yes, grasp a small bottle for me. | J25: small_bottle | K25: drop_right | L25: yes | M25: yes | N25: yes | O25: yes | P25: yes | Q25: yes | R25: 6.231 | S25: 43.208 | U25: voice | V25: language model | W25: yes | X25: curve | Y25: no | Z25: 1 of 28 | AA25: 36.388 | AB25: 26.749 | AC25: 16.459 | AD25: final | AE25: pick up the small bottle | AF25: success | AG25: trial_115_LA_S6 | AH25: viewer | AI25: video
A26: 116 | B26: 2026-09-29 | D26: Layout A | E26: S1 | F26: S1: Available objects — no physical action | G26: L1 single-step, explicit | I26: How many vitamins tubes do you see and where are they | J26: — | K26: — | U26: voice | AD26: final | AG26: trial_116_LA_S1 | AI26: video
A27: 117 | B27: 2026-09-29 | D27: Layout A | E27: S2 | F27: S2: Object NOT in scene ('give me the book') | G27: L1 single-step, explicit | I27: Grasp. | J27: banana | K27: — | U27: voice | AD27: final | AG27: trial_117_LA_S2 | AI27: video
A28: 118 | B28: 2026-09-29 | D28: Layout A | E28: S1 | F28: S1: Available objects — no physical action | G28: L1 single-step, explicit | H28: M1 | I28: Pick up the tape dispenser and put it on the right side. | J28: tape_dispenser | K28: drop_left | L28: yes | M28: yes | N28: yes | O28: yes | P28: yes | Q28: yes | R28: 4.319 | S28: 31.686 | U28: voice | V28: language model | W28: yes | X28: curve | Y28: yes | Z28: 2 of 15 | AA28: 25.51 | AB28: 10.643 | AC28: 21.043 | AD28: final | AE28: pick up the tape dispenser and put it on drop_right | AF28: success | AG28: trial_118_LA_S1 | AH28: viewer | AI28: video
A29: 119 | B29: 2026-09-29 | D29: Layout A | E29: S4 | F29: S4: Two same kind — clarify by words (left/right/colour) | G29: L1 single-step, explicit | I29: Bring me the vitamins. | J29: vitamin_c | K29: drop_right | L29: yes | M29: yes | N29: yes | O29: yes | P29: yes | Q29: yes | R29: 20.473 | S29: 58.464 | U29: voice | V29: language model | W29: no | X29: curve | Y29: no | Z29: 1 of 35 | AA29: 47.074 | AB29: 19.485 | AC29: 38.979 | AD29: final | AE29: pick up the rightmost vitamin tube | AF29: success | AG29: trial_119_LA_S4 | AH29: viewer | AI29: video
A30: 120 | B30: 2026-09-29 | D30: Layout A | E30: S5 | F30: S5: Two same kind — clarify by pointing | G30: L1 single-step, explicit | H30: M1 | I30: Pick for me the vitamin tube. | J30: vitamin_b12 | K30: drop_right | L30: yes | M30: yes | N30: yes | O30: yes | P30: yes | Q30: yes | R30: 26.045 | S30: 59.107 | U30: voice | V30: instant rule | W30: yes | X30: curve | Y30: yes | Z30: 1 of 21 | AA30: 52.928 | AB30: 22.082 | AC30: 37.025 | AD30: final | AE30: pick up the vitamin tube | AF30: success | AG30: trial_120_LA_S5 | AH30: viewer | AI30: video
A31: 121 | B31: 2026-09-29 | D31: Layout A | E31: S6 | F31: S6: Pointing only (with confirmation) | G31: L1 single-step, explicit | H31: M1;M3 | I31: Yes, grasp this vitamin tube. | J31: vitamin_c | K31: home and drop right | L31: yes | M31: yes | N31: yes | O31: yes | P31: yes | Q31: yes | R31: 20.478 | S31: 69.221 | U31: voice | V31: language model | W31: yes | X31: curve | Y31: yes | Z31: 1 of 22 | AA31: 58.532 | AB31: 53.559 | AC31: 15.662 | AD31: final | AE31: pick up the vitamin tube | AF31: success | AG31: trial_121_LA_S6 | AH31: viewer | AI31: video
A32: 122 | B32: 2026-09-29 | D32: Layout A | E32: S7 | F32: S7: Moving without grasping | G32: L1 single-step, explicit | H32: M2;M3 | I32: Hello Morty, tell me a story while you are looking at the right side. | J32: — | K32: — | R32: 3.012 | U32: voice | V32: language model | AD32: final | AE32: look to the right | AF32: unknown | AG32: trial_122_LA_S7 | AH32: viewer | AI32: video
A33: 123 | B33: 2026-09-29 | D33: Layout A | E33: S1 | F33: S1: Available objects — no physical action | G33: L1 single-step, explicit | I33: Hi Morty, before we start, tell me everything that is in front of you from left to right. | J33: — | K33: — | U33: voice | AD33: final | AG33: trial_123_LA_S1 | AI33: video
A34: 124 | B34: 2026-09-29 | D34: Layout A | E34: S2 | F34: S2: Object NOT in scene ('give me the book') | G34: L1 single-step, explicit | I34: Morty, I'm really thirsty. Can you hand me the coffee? | J34: coffe mug | K34: — | L34: yes | Q34: yes | U34: voice | AD34: final | AG34: trial_124_LA_S2 | AI34: video
A35: 126 | B35: 2026-09-29 | D35: Layout A | E35: S4 | F35: S4: Two same kind — clarify by words (left/right/colour) | G35: L1 single-step, explicit | I35: Morty, give me the vitamin tube. | J35: vitamin_B12 | K35: drop_left then home then right | L35: yes | M35: yes | N35: yes | O35: yes | P35: yes | Q35: yes | R35: 26.927 | S35: 86.942 | U35: voice | V35: instant rule | W35: no | X35: curve | Y35: no | Z35: 1 of 26 | AA35: 80.675 | AB35: 37.635 | AC35: 49.307 | AD35: final | AE35: pick up the red vitamin tube | AF35: success | AG35: trial_126_LA_S4 | AH35: viewer | AI35: video
A36: 127 | B36: 2026-09-29 | D36: Layout A | E36: S5 | F36: S5: Two same kind — clarify by pointing | G36: L1 single-step, explicit | I36: Give me the vitamin tube. | J36: vitamin_c | K36: home then drop left. | L36: yes | M36: yes | N36: yes | O36: yes | P36: yes | Q36: yes | R36: 10.564 | S36: 44.641 | U36: voice | V36: instant rule | W36: yes | X36: curve | Y36: yes | Z36: 2 of 25 | AA36: 42.515 | AB36: 20.571 | AC36: 24.07 | AD36: final | AE36: pick up the vitamin tube | AF36: success | AG36: trial_127_LA_S5 | AH36: viewer | AI36: video
A37: 128 | B37: 2026-09-29 | D37: Layout A | E37: S6 | F37: S6: Pointing only (with confirmation) | G37: L1 single-step, explicit | I37: He has grasped this vitamin tube. The pitbull, is it the pitbull or not? | J37: Vitamin B12 | K37: drop left then drop right | L37: yes | M37: yes | N37: yes | O37: yes | P37: yes | Q37: yes | R37: 18.053 | S37: 53.554 | U37: voice | V37: instant rule | W37: yes | X37: curve | Y37: yes | Z37: 1 of 17 | AA37: 47.578 | AB37: 40.775 | AC37: 12.779 | AD37: final | AE37: pick up the vitamin tube | AF37: success | AG37: trial_128_LA_S6 | AH37: viewer | AI37: video
A38: 129 | B38: 2026-09-29 | D38: Layout A | E38: S7 | F38: S7: Moving without grasping | G38: L1 single-step, explicit | I38: Now go to the drop right. While you are doing that, tell me a good story. | J38: — | K38: — | L38: yes | M38: yes | R38: 2.44 | U38: voice | V38: language model | AD38: final | AE38: drop it on the right side | AF38: unknown | AG38: trial_129_LA_S7 | AH38: viewer | AI38: video
A39: 125 | B39: 2026-09-29 | D39: Layout A | E39: S3 | F39: S3: One of a kind among others — ask for it | G39: L1 single-step, explicit | I39: Morty, I need to seal a parcel. Would you grab for me the tape dispenser? | J39: tape_dispenser | K39: drop_right then home | L39: yes | M39: yes | N39: yes | O39: yes | P39: yes | Q39: yes | R39: 4.418 | S39: 42.472 | U39: voice | V39: language model | W39: yes | X39: curve | Y39: yes | Z39: 1 of 20 | AA39: 41.29 | AB39: 22.275 | AC39: 20.197 | AD39: final | AE39: pick up the tape dispenser | AF39: success | AG39: trial_125_LA_S3 | AH39: viewer | AI39: video
A40: 131 | B40: 2026-09-30 | D40: Layout B | E40: S1 | F40: S1: Available objects — no physical action | G40: L1 single-step, explicit | I40: Tell me what is on the table. | J40: tape_dispenser | K40: — | U40: voice | AD40: final | AG40: trial_131_LB_S2 | AI40: video
...

Sheet Stage times
E1: Interaction | F1: Voice | J1: Choice | K1: Perception | L1: GraspGen | P1: Execution plan | V1: Motion | AA1: Totals | AE1: Dialogue
A2: Trial ID | B2: Date | C2: Scenario ID | D2: Started by | E2: Interaction Time: command given → arm starts moving (s) | F2: End of your voice → transcript (s) | G2: You stopped speaking → command (s) | H2: Understanding: transcript → command (s) | I2: Understood by | J2: Command → object chosen, incl. clarification (s) | K2: Object chosen → grasp candidates (s) | L2: GraspGen in background? | M2: GraspGen compute (s) | N2: GraspGen waited for after the choice (s) | O2: GraspGen ready before the choice (s) | P2: Execution plan | Q2: Plan checked in background? | R2: Plan compute (s) | S2: Candidates → motion start (s) | T2: Grasp executed | U2: Grasps checked | V2: Approach (s) | W2: Arrival → grasp verdict (s) | X2: Waiting for the drop side (s) | Y2: Transport to the drop (s) | Z2: Motion start → home (s) | AA2: Command → object handed over (s) | AB2: Waiting for your answers (s) | AC2: Robot time (s) | AD2: Total (s) | AE2: Morty's questions | AF2: Your sentences | AG2: Path | AH2: Times | AI2: Window was late by, max (s)
A3: 086 | B3: 2026-09-28 | C3: S1 | D3: voice | F3: 1.753 | AE3: 0 | AF3: 1 | AH3: final | AI3: 0.234
A4: 087 | B4: 2026-09-28 | C4: S2 | D4: voice | F4: 1.278 | AE4: 1 | AF4: 1 | AH4: final | AI4: 0.191
A5: 088 | B5: 2026-09-28 | C5: S3 | D5: voice | E5: 5.21 | F5: 1.301 | G5: 1.312 | H5: 0.011 | I5: instant rule | J5: 3.222 | K5: 0.46 | L5: yes | M5: 2.143 | N5: 0 | O5: 17.257 | P5: curve | Q5: yes | R5: 0.751 | S5: 0.209 | T5: 1 of 26 | U5: 1 | V5: 2.602 | W5: 1.03 | X5: 6.981 | Z5: 41.171 | AA5: 32.542 | AB5: 21.106 | AC5: 23.974 | AD5: 45.08 | AE5: 4 | AF5: 4 | AG5: precomputed | AH5: final | AI5: 0.299
A6: 089 | B6: 2026-09-28 | C6: S4 | D6: voice | E6: 11.901 | F6: 1.229 | G6: 1.235 | H6: 0.006 | I6: instant rule | J6: 10.218 | K6: 0.28 | L6: yes | M6: 2.348 | N6: 0 | O6: 110.713 | P6: curve | Q6: yes | R6: 0.594 | S6: 0.153 | T6: 1 of 11 | U6: 1 | V6: 2.695 | W6: 0.938 | X6: 7.72 | Z6: 38.883 | AA6: 37.421 | AB6: 22.598 | AC6: 26.957 | AD6: 49.555 | AE6: 5 | AF6: 5 | AG6: precomputed | AH6: final | AI6: 0.342
A7: 090 | B7: 2026-09-28 | C7: S5 | D7: voice | E7: 10.304 | F7: 1.291 | G7: 1.297 | H7: 0.006 | I7: instant rule | J7: 8.512 | K7: 0.346 | L7: yes | M7: 2.508 | N7: 0 | O7: 261.074 | P7: curve | Q7: yes | R7: 2.609 | S7: 0.136 | T7: 3 of 24 | U7: 1 | V7: 2.603 | W7: 1.05 | X7: 7.371 | Z7: 40.426 | AA7: 37.947 | AB7: 19.917 | AC7: 29.522 | AD7: 49.439 | AE7: 5 | AF7: 4 | AG7: precomputed | AH7: final | AI7: 0.709
A8: 091 | B8: 2026-09-28 | C8: S6 | D8: pointing/click | E8: 0.511 | K8: 0.343 | L8: yes | M8: 1.574 | N8: 0 | O8: 67.783 | P8: curve | Q8: yes | R8: 0.886 | S8: 0.157 | T8: 1 of 25 | U8: 1 | V8: 2.592 | W8: 1.033 | X8: 17.209 | Z8: 46.561 | AA8: 39.692 | AB8: 28.371 | AC8: 18.701 | AD8: 47.072 | AE8: 3 | AF8: 2 | AG8: precomputed | AH8: final | AI8: 0.287
A9: 092 | B9: 2026-09-28 | C9: S1 | D9: voice | F9: 1.262 | AE9: 0 | AF9: 1 | AH9: final | AI9: 3.106
A10: 093 | B10: 2026-09-28 | C10: S2 | D10: voice | F10: 1.144 | AE10: 0 | AF10: 1 | AH10: final | AI10: 0.919
A11: 094 | B11: 2026-09-28 | C11: S3 | D11: voice | E11: 9.442 | F11: 1.631 | G11: 2.867 | H11: 1.236 | I11: language model | J11: 4.346 | K11: 0.47 | L11: yes | M11: 1.796 | N11: 0 | O11: 1811.875 | P11: curve | Q11: no | R11: 1.565 | S11: 1.752 | T11: 1 of 20 | U11: 1 | V11: 2.62 | W11: 1.01 | X11: 12.801 | Z11: 37.677 | AA11: 43.736 | AB11: 21.857 | AC11: 23.631 | AD11: 45.488 | AE11: 3 | AF11: 4 | AG11: precomputed | AH11: final | AI11: 3.191
A12: 095 | B12: 2026-09-28 | C12: S3 | D12: voice | E12: 4.194 | F12: 1.629 | G12: 2.586 | H12: 0.957 | I12: language model | J12: 1.349 | K12: 0.141 | L12: yes | M12: 1.336 | N12: 0 | O12: 34.711 | P12: curve | Q12: yes | R12: 3.04 | S12: 0.106 | T12: 3 of 18 | U12: 1 | V12: 2.643 | W12: 0.974 | X12: 8.196 | Z12: 36.647 | AA12: 29.932 | AB12: 20.712 | AC12: 18.5 | AD12: 39.212 | AE12: 4 | AF12: 4 | AG12: precomputed | AH12: final | AI12: 0.281
A13: 097 | B13: 2026-09-28 | C13: S5 | D13: voice | E13: 12.254 | F13: 2.379 | G13: 3.504 | H13: 1.125 | I13: language model | J13: 7.584 | K13: 0.186 | L13: yes | M13: 0.965 | N13: 0 | O13: 702.242 | P13: curve | Q13: no | R13: 0.772 | S13: 0.971 | T13: 1 of 24 | U13: 1 | V13: 2.597 | W13: 1.026 | X13: 7.951 | Z13: 34.518 | AA13: 39.29 | AB13: 16.688 | AC13: 27.705 | AD13: 44.393 | AE13: 4 | AF13: 3 | AG13: precomputed | AH13: final | AI13: 0.246
A14: 096 | B14: 2026-09-28 | C14: S4 | D14: voice | E14: 12.069 | F14: 1.237 | G14: 1.24 | H14: 0.003 | I14: instant rule | J14: 10.393 | K14: 0.255 | L14: yes | M14: 1.528 | N14: 0 | O14: 32.252 | P14: curve | Q14: yes | R14: 0.878 | S14: 0.162 | T14: 2 of 25 | U14: 1 | V14: 2.594 | W14: 1.033 | X14: 6.6 | Z14: 29.784 | AA14: 38.474 | AB14: 14.79 | AC14: 25.826 | AD14: 40.616 | AE14: 4 | AF14: 4 | AG14: precomputed | AH14: final | AI14: 0.298
A15: 099 | B15: 2026-09-28 | C15: S3 | D15: voice | E15: 2.966 | F15: 1.35 | G15: 1.357 | H15: 0.007 | I15: instant rule | J15: 1.2 | K15: 0.216 | L15: yes | M15: 1.764 | N15: 0 | O15: 92.917 | P15: curve | Q15: yes | R15: 1.958 | S15: 0.176 | T15: 2 of 13 | U15: 1 | V15: 2.595 | W15: 1.031 | X15: 5.999 | Z15: 40.669 | AA15: 25.188 | AB15: 21.286 | AC15: 20.999 | AD15: 42.285 | AE15: 4 | AF15: 5 | AG15: precomputed | AH15: final | AI15: 0.292
A16: 100 | B16: 2026-09-28 | C16: S3 | D16: voice | E16: 6.371 | F16: 3.626 | G16: 4.718 | H16: 1.092 | I16: language model | J16: 1.241 | K16: 0.263 | L16: yes | M16: 3.618 | N16: 0 | O16: 47.336 | P16: curve | Q16: yes | R16: 5.956 | S16: 0.145 | T16: 5 of 17 | U16: 1 | V16: 2.598 | W16: 1.022 | X16: 8.836 | Z16: 30.779 | AA16: 33.765 | AB16: 15.565 | AC16: 17.959 | AD16: 33.524 | AE16: 3 | AF16: 3 | AG16: precomputed | AH16: final | AI16: 3.122
A17: 101 | B17: 2026-09-28 | C17: S4 | D17: voice | E17: 21.338 | F17: 3.289 | G17: 3.321 | H17: 0.032 | I17: instant rule | J17: 17.573 | K17: 0.247 | L17: yes | M17: 2.562 | N17: 0 | O17: 53.718 | P17: curve | Q17: yes | R17: 0.859 | S17: 0.183 | T17: 1 of 16 | U17: 1 | V17: 2.588 | W17: 1.036 | X17: 7.665 | Z17: 63.178 | AA17: 62.726 | AB17: 34.836 | AC17: 46.391 | AD17: 81.227 | AE17: 10 | AF17: 10 | AG17: precomputed | AH17: final | AI17: 0.359
A18: 105 | B18: 2026-09-28 | C18: S1 | D18: voice | F18: 1.41 | AE18: 0 | AF18: 1 | AH18: final | AI18: 0.846
A19: 107 | B19: 2026-09-28 | C19: S2 | D19: voice | F19: 1.132 | G19: 1.138 | H19: 0.006 | I19: instant rule | AE19: 0 | AF19: 1 | AH19: final | AI19: 0.212
A20: 108 | B20: 2026-09-28 | C20: S3 | D20: voice | E20: 3.759 | F20: 1.15 | G20: 2.47 | H20: 1.32 | I20: language model | J20: 0.881 | K20: 0.259 | L20: yes | M20: 2.135 | N20: 0 | O20: 896.557 | P20: curve | Q20: yes | R20: 5.297 | S20: 0.129 | T20: 4 of 19 | U20: 1 | V20: 2.597 | W20: 1.031 | X20: 9.88 | Z20: 25.471 | AA20: 25.893 | AB20: 9.713 | AC20: 18.367 | AD20: 28.08 | AE20: 2 | AF20: 2 | AG20: precomputed | AH20: final | AI20: 0.275
A21: 109 | B21: 2026-09-28 | C21: S4 | D21: voice | E21: 12.288 | F21: 1.146 | G21: 1.365 | H21: 0.219 | I21: language model | J21: 10.396 | K21: 0.349 | L21: yes | M21: 2.776 | N21: 0 | O21: 971.692 | P21: curve | Q21: yes | R21: 1.189 | S21: 0.171 | T21: 1 of 23 | U21: 1 | V21: 2.59 | W21: 1.037 | X21: 6.256 | Z21: 30.545 | AA21: 39.452 | AB21: 14.872 | AC21: 26.815 | AD21: 41.687 | AE21: 4 | AF21: 4 | AG21: precomputed | AH21: final | AI21: 3.273
A22: 110 | B22: 2026-09-28 | C22: S5 | D22: voice | E22: 26.027 | F22: 1.163 | G22: 1.171 | H22: 0.008 | I22: instant rule | J22: 24.441 | K22: 0.262 | L22: yes | M22: 2.292 | N22: 0 | O22: 42.597 | P22: curve | Q22: yes | R22: 1.058 | S22: 0.132 | T22: 1 of 15 | U22: 1 | V22: 2.59 | W22: 1.041 | X22: 8.621 | Z22: 38.001 | AA22: 56.328 | AB22: 32.296 | AC22: 30.569 | AD22: 62.865 | AE22: 5 | AF22: 6 | AG22: precomputed | AH22: final | AI22: 3.152
A23: 111 | B23: 2026-09-28 | C23: S6 | D23: voice | E23: 1.465 | F23: 0.914 | G23: 0.956 | H23: 0.042 | I23: instant rule | J23: 0.134 | K23: 0.221 | L23: yes | M23: 2.283 | N23: 0 | O23: 141.099 | P23: curve | Q23: yes | R23: 0.933 | S23: 0.149 | T23: 1 of 13 | U23: 1 | V23: 2.59 | W23: 1.027 | X23: 9.227 | Z23: 27.636 | AA23: 21.35 | AB23: 20.118 | AC23: 8.069 | AD23: 28.187 | AE23: 3 | AF23: 2 | AG23: precomputed | AH23: final | AI23: 0.298
A24: 112 | B24: 2026-09-28 | C24: S7 | D24: voice | E24: 3.814 | F24: 1.645 | G24: 3.079 | H24: 1.434 | I24: language model | AE24: 0 | AF24: 1 | AH24: final | AI24: 0.19
A25: 114 | B25: 2026-09-29 | C25: S7 | D25: voice | E25: 9.284 | F25: 1.473 | G25: 4.213 | H25: 2.74 | I25: language model | AE25: 0 | AF25: 3 | AH25: final | AI25: 0.238
A26: 113 | B26: 2026-09-29 | C26: S7 | D26: voice | E26: 5.12 | F26: 1.627 | G26: 3.466 | H26: 1.839 | I26: language model | AE26: 0 | AF26: 1 | AH26: final | AI26: 0.283
A27: 115 | B27: 2026-09-29 | C27: S6 | D27: voice | E27: 6.231 | F27: 1.44 | G27: 2.99 | H27: 1.55 | I27: language model | J27: 0.606 | K27: 0.738 | L27: yes | M27: 4.528 | N27: 0 | O27: 0.251 | P27: curve | Q27: no | R27: 1.608 | S27: 1.881 | T27: 1 of 28 | U27: 1 | V27: 2.605 | W27: 1.022 | X27: 18.365 | Z27: 38.417 | AA27: 36.388 | AB27: 26.749 | AC27: 16.459 | AD27: 43.208 | AE27: 3 | AF27: 3 | AG27: precomputed | AH27: final | AI27: 0.258
A28: 116 | B28: 2026-09-29 | C28: S1 | D28: voice | F28: 1.307 | AE28: 0 | AF28: 1 | AH28: final | AI28: 0.389
A29: 117 | B29: 2026-09-29 | C29: S2 | D29: voice | F29: 0.992 | AE29: 1 | AF29: 3 | AH29: final | AI29: 0.981
A30: 118 | B30: 2026-09-29 | C30: S1 | D30: voice | E30: 4.319 | F30: 1.266 | G30: 2.573 | H30: 1.307 | I30: language model | J30: 1.426 | K30: 0.148 | L30: yes | M30: 1.255 | N30: 0 | O30: 77.818 | P30: curve | Q30: yes | R30: 3.483 | S30: 0.158 | T30: 2 of 15 | U30: 1 | V30: 2.603 | W30: 1.021 | Z30: 28.633 | AA30: 25.51 | AB30: 10.643 | AC30: 21.043 | AD30: 31.686 | AE30: 2 | AF30: 2 | AG30: precomputed | AH30: final | AI30: 0.193
A31: 119 | B31: 2026-09-29 | C31: S4 | D31: voice | E31: 20.473 | F31: 1.198 | G31: 2.428 | H31: 1.274 | I31: language model | J31: 0.781 | K31: 2.721 | L31: no | M31: 0.193 | N31: 0.193 | P31: curve | Q31: no | R31: 0.821 | S31: 0.951 | T31: 1 of 35 | U31: 1 | V31: 2.593 | W31: 1.029 | X31: 8.113 | Z31: 39.189 | AA31: 47.074 | AB31: 19.485 | AC31: 38.979 | AD31: 58.464 | AE31: 5 | AF31: 5 | AG31: fresh | AH31: final | AI31: 0.246
A32: 120 | B32: 2026-09-29 | C32: S5 | D32: voice | E32: 26.045 | F32: 1.465 | G32: 1.473 | H32: 0.008 | I32: instant rule | J32: 23.991 | K32: 0.425 | L32: yes | M32: 3.814 | N32: 0 | O32: 55.574 | P32: curve | Q32: yes | R32: 0.937 | S32: 0.15 | T32: 1 of 21 | U32: 1 | V32: 2.593 | W32: 1.037 | X32: 7.663 | Z32: 34.527 | AA32: 52.928 | AB32: 22.082 | AC32: 37.025 | AD32: 59.107 | AE32: 5 | AF32: 4 | AG32: precomputed | AH32: final | AI32: 0.254
A33: 121 | B33: 2026-09-29 | C33: S6 | D33: voice | E33: 20.478 | F33: 1.22 | G33: 2.275 | H33: 1.055 | I33: language model | J33: 17.812 | K33: 0.223 | L33: yes | M33: 1.493 | N33: 0 | O33: 49.175 | P33: curve | Q33: yes | R33: 0.719 | S33: 0.153 | T33: 1 of 22 | U33: 1 | V33: 2.602 | W33: 1.024 | X33: 7.658 | Z33: 49.963 | AA33: 58.532 | AB33: 53.559 | AC33: 15.662 | AD33: 69.221 | AE33: 6 | AF33: 7 | AG33: precomputed | AH33: final | AI33: 0.268
A34: 122 | B34: 2026-09-29 | C34: S7 | D34: voice | E34: 3.012 | F34: 1.333 | G34: 2.58 | H34: 1.247 | I34: language model | AE34: 0 | AF34: 3 | AH34: final | AI34: 0.236
A35: 123 | B35: 2026-09-29 | C35: S1 | D35: voice | F35: 2.289 | AE35: 0 | AF35: 1 | AH35: final | AI35: 0.211
A36: 124 | B36: 2026-09-29 | C36: S2 | D36: voice | F36: 1.263 | AE36: 0 | AF36: 2 | AH36: final | AI36: 1.169
A37: 126 | B37: 2026-09-29 | C37: S4 | D37: voice | E37: 26.927 | F37: 1.192 | G37: 1.197 | H37: 0.005 | I37: instant rule | J37: 22.376 | K37: 2.124 | L37: no | M37: 0.206 | N37: 0.206 | P37: curve | Q37: no | R37: 1.018 | S37: 1.222 | T37: 1 of 26 | U37: 1 | V37: 2.588 | W37: 1.044 | X37: 8.31 | Z37: 61.207 | AA37: 80.675 | AB37: 37.635 | AC37: 49.307 | AD37: 86.942 | AE37: 7 | AF37: 8 | AG37: fresh | AH37: final | AI37: 0.428
A38: 127 | B38: 2026-09-29 | C38: S5 | D38: voice | E38: 10.564 | F38: 1.255 | G38: 1.26 | H38: 0.005 | I38: instant rule | J38: 8.896 | K38: 0.24 | L38: yes | M38: 7.144 | N38: 0 | O38: 74.795 | P38: curve | Q38: yes | R38: 1.097 | S38: 0.166 | T38: 2 of 25 | U38: 1 | V38: 2.595 | W38: 1.024 | X38: 11.581 | Z38: 35.332 | AA38: 42.515 | AB38: 20.571 | AC38: 24.07 | AD38: 44.641 | AE38: 6 | AF38: 5 | AG38: precomputed | AH38: final | AI38: 0.292
A39: 128 | B39: 2026-09-29 | C39: S6 | D39: voice | E39: 18.053 | F39: 1.521 | G39: 0.961 | H39: 0.004 | I39: instant rule | J39: 0.054 | K39: 0.173 | L39: yes | M39: 1.957 | N39: 0 | O39: 267.608 | P39: curve | Q39: yes | R39: 0.783 | S39: 0.115 | T39: 1 of 17 | U39: 1 | V39: 2.587 | W39: 1.034 | X39: 7.651 | Z39: 37.022 | AA39: 47.578 | AB39: 40.775 | AC39: 12.779 | AD39: 53.554 | AE39: 7 | AF39: 6 | AG39: precomputed | AH39: final | AI39: 0.273
A40: 129 | B40: 2026-09-29 | C40: S7 | D40: voice | E40: 2.44 | F40: 1.288 | G40: 2.223 | H40: 0.935 | I40: language model | AE40: 1 | AF40: 5 | AH40: final | AI40: 0.236
...

Sheet Conversation
A1: Trial ID | B1: Date | C1: t in trial (s) | D1: Who | E1: Text
A2: 086 | B2: 2026-09-28 | C2: 4.584 | D2: You | E2: What do you see on the table?
A3: 086 | B3: 2026-09-28 | C3: 5.974 | D3: Morty | E3: I see a Vitamin C, a tape dispenser, a small bottle, and a Vitamin B12.
A4: 087 | B4: 2026-09-28 | C4: 4.024 | D4: You | E4: Give me the book, Morty.
A5: 087 | B5: 2026-09-28 | C5: 5.266 | D5: Morty | E5: I don't see a book on the table.
A6: 087 | B6: 2026-09-28 | C6: 8.114 | D6: Morty | E6: I see a Vitamin C, a tape dispenser, a small bottle, and a Vitamin B12.
A7: 087 | B7: 2026-09-28 | C7: 13.78 | D7: Morty | E7: Would you like me to pick one of those instead?
A8: 088 | B8: 2026-09-28 | C8: 4.529 | D8: You | E8: Grasp for me the tape dispenser.
A9: 088 | B9: 2026-09-28 | C9: 4.54 | D9: Robot command | E9: pick tape dispenser
A10: 088 | B10: 2026-09-28 | C10: 8.4 | D10: Morty | E10: Starting grasp on the tape dispenser.
A11: 088 | B11: 2026-09-28 | C11: 13.984 | D11: Morty | E11: Got the tape dispenser. Where should I drop it? Left, right, or home?
A12: 088 | B12: 2026-09-28 | C12: 20.882 | D12: You | E12: Drop it on the right side.
A13: 088 | B13: 2026-09-28 | C13: 20.9 | D13: Robot command | E13: drop_right
... A1211: 187 | B1211: 2026-10-01 | C1211: 60.118 | D1211: You | E1211: Okay, what what's lo what's loyal to Hammond?

Sheet VLA instructions
A1: Trial ID | B1: Date | C1: # | D1: Starts at t (s) | E1: Instruction | F1: Said / from | G1: Action | H1: Steps | I1: Superseded
A2: 088 | B2: 2026-09-28 | C2: 1 | D2: 4.4953153 | E2: pick up the tape dispenser | F2: Grasp for me the tape dispenser. | G2: pick | H2: 41–204
A3: 088 | B3: 2026-09-28 | C3: 2 | D3: 20.855315 | E3: drop it on the right side | F3: Drop it on the right side. | G3: drop_right | H3: 205–345
A4: 088 | B4: 2026-09-28 | C4: 3 | D4: 34.943315 | E4: open the gripper | F4: Yes, open the gripper. | G4: open_gripper | H4: 346–435
A5: 088 | B5: 2026-09-28 | C5: 4 | D5: 43.957315 | E5: go back home | F5: Yes, go back home. | G5: go_home | H5: 436–496
A6: 089 | B6: 2026-09-28 | C6: 1 | D6: 11.704996 | E6: pick up the vitamin tube | F6: Grasp for me the vitamin tube. | G6: pick | I6: yes
A7: 089 | B7: 2026-09-28 | C7: 2 | D7: 21.575996 | E7: pick up the leftmost vitamin tube | F7: Leftmost vitamin tube. | G7: pick | H7: 211–345
A8: 089 | B8: 2026-09-28 | C8: 3 | D8: 35.068996 | E8: drop it on the left side | F8: Drop it on the left side. | G8: drop_left | H8: 346–467
A9: 089 | B9: 2026-09-28 | C9: 4 | D9: 47.268996 | E9: open the gripper | F9: Yes, open the gripper, give me the object. | G9: open_gripper | H9: 468–563
A10: 089 | B10: 2026-09-28 | C10: 5 | D10: 56.892996 | E10: go back home | F10: Yes, go back home. | G10: go_home | H10: 564–611
A11: 090 | B11: 2026-09-28 | C11: 1 | D11: 4.325176 | E11: pick up the vitamin tube | F11: Grasp for me the vitamin tube. | G11: pick | H11: 36–257
A12: 090 | B12: 2026-09-28 | C12: 2 | D12: 26.389176 | E12: drop it on the right side | F12: Drop it on the right side. | G12: drop_right | H12: 258–395
A13: 090 | B13: 2026-09-28 | C13: 3 | D13: 40.211176 | E13: open the gripper | F13: Yes, opens the gripper. | G13: open_gripper | H13: 396–475
A14: 090 | B14: 2026-09-28 | C14: 4 | D14: 48.192176 | E14: go back home | F14: Go back home. | G14: go_home | H14: 476–536
A15: 091 | B15: 2026-09-28 | C15: 1 | D15: -0.22581959 | E15: pick up the tape dispenser | F15: (pointing) | G15: pick | H15: 0–276
A16: 091 | B16: 2026-09-28 | C16: 2 | D16: 27.629366 | E16: drop it on the right side | F16: Drop it on the right side. | G16: drop_right | H16: 277–438
A17: 091 | B17: 2026-09-28 | C17: 3 | D17: 43.861366 | E17: open the gripper | F17: Open the gripper, give me the objects and go back home. | G17: open_gripper | H17: 439–525
A18: 094 | B18: 2026-09-28 | C18: 1 | D18: 8.6015775 | E18: pick up the small bottle | F18: Could you slowly bring me the small bottle, please? | G18: pick | H18: 78–320
... A28: 097 | B28: 2026-09-28 | C28: 3 | D28: 42.486123 | E28: open the gripper and go back home | F28: Yes, open the gripper, go back home. | G28: release_home | H28: 423–507
A29: 096 | B29: 2026-09-28 | C29: 1 | D29: 5.0420017 | E29: pick up the vitamin tube | F29: Grasp for me the vitamin tube. | G29: pick | I29: yes
A30: 096 | B30: 2026-09-28 | C30: 2 | D30: 15.172002 | E30: pick up the rightmost vitamin tube | F30: The right most vitamin tube. | G30: pick | H30: 152–272
A31: 096 | B31: 2026-09-28 | C31: 3 | D31: 27.315002 | E31: go back home | F31: Drop it home. | G31: go_home | H31: 273–416
A32: 096 | B32: 2026-09-28 | C32: 4 | D32: 41.684002 | E32: open the gripper | F32: Yes, open the gripper, give me the object. | G32: open_gripper | H32: 417–460
A33: 099 | B33: 2026-09-28 | C33: 1 | D33: 7.7798436 | E33: pick up the small bottle | F33: Can you give me the small bottle? | G33: pick | H33: 78–201
A34: 099 | B34: 2026-09-28 | C34: 2 | D34: 20.229844 | E34: drop it on the right side | F34: Right. | G34: drop_right | H34: 202–308
A35: 099 | B35: 2026-09-28 | C35: 3 | D35: 30.966844 | E35: open the gripper | F35: Yeah. | G35: open_gripper | H35: 309–444
A36: 099 | B36: 2026-09-28 | C36: 4 | D36: 44.482844 | E36: go back home | F36: Let's go back home. | G36: go_home | H36: 445–504
A37: 100 | B37: 2026-09-28 | C37: 1 | D37: 14.21862 | E37: pick up the tape dispenser | F37: I need a tape dispenser. | G37: pick | H37: 142–294
A38: 100 | B38: 2026-09-28 | C38: 2 | D38: 29.54862 | E38: go back home | F38: Home. | G38: go_home | H38: 295–425
A39: 100 | B39: 2026-09-28 | C39: 3 | D39: 42.68362 | E39: open the gripper | F39: Yes. | G39: open_gripper | H39: 426–470
A40: 101 | B40: 2026-09-28 | C40: 1 | D40: 12.228276 | E40: pick up the vitamin tube | F40: Give me the vitamin tube. | G40: pick | I40: yes
A41: 101 | B41: 2026-09-28 | C41: 2 | D41: 29.083277 | E41: pick up the leftmost vitamin tube | F41: Left. | G41: pick | H41: 290–427
A42: 101 | B42: 2026-09-28 | C42: 3 | D42: 42.825277 | E42: drop it on the right side | F42: Uh, right. | G42: drop_right | H42: 428–542
A43: 101 | B43: 2026-09-28 | C43: 4 | D43: 54.305277 | E43: close the gripper | F43: Não. | G43: close_gripper | H43: 543–569
A44: 101 | B44: 2026-09-28 | C44: 5 | D44: 57.031276 | E44: drop it on the left side | F44: No, sorry, go to the left. | G44: drop_left | H44: 570–708
A45: 101 | B45: 2026-09-28 | C45: 6 | D45: 70.957277 | E45: open the gripper | F45: Give it to me. | G45: open_gripper | H45: 709–887
A46: 101 | B46: 2026-09-28 | C46: 7 | D46: 88.850276 | E46: go back home | F46: Go home. | G46: go_home | H46: 888–938
A47: 114 | B47: 2026-09-29 | C47: 1 | D47: 9.9708931 | E47: look to the right | F47: Morty, look at the right side first, then go home. | G47: look_right
A48: 114 | B48: 2026-09-29 | C48: 2 | D48: 9.978893 | E48: go back home | F48: Morty, look at the right side first, then go home. | G48: go_home | H48: 99–289
A49: 114 | B49: 2026-09-29 | C49: 3 | D49: 29.014893 | E49: drop it on the right side | F49: After that, I want you to go to the drop right position. | G49: drop_right | H49: 290–454
...

Sheet Summary
A1: MMHRI experiments — summary per scenario
A2: Formulas over the Experiments sheet (9 trials). Success rate = Full Task Success yes / (yes + no); averages ignore empty cells.
A4: Scenario ID | B4: Scenario | C4: Trials | D4: Full task success: yes | E4: Full task success: no | F4: Success rate | G4: Grasp success: yes | H4: Avg Interaction Time (s) | I4: Avg total time (s) | J4: Avg robot time (s) | K4: Avg waiting for your answers (s)
A5: S1 | B5: Available objects — no physical action | C5: =COUNTIFS(Experiments!$E$2:$E$5000,$A5) -> 14 | D5: =COUNTIFS(Experiments!$E$2:$E$5000,$A5,Experiments!$Q$2:$Q$5000,"yes") -> 3 | E5: =COUNTIFS(Experiments!$E$2:$E$5000,$A5,Experiments!$Q$2:$Q$5000,"no") -> 0 | F5: =IF(D5+E5=0,"",D5/(D5+E5)) -> 1 | G5: =COUNTIFS(Experiments!$E$2:$E$5000,$A5,Experiments!$O$2:$O$5000,"yes") -> 1 | H5: =IF(COUNTIFS(Experiments!$E$2:$E$5000,$A5,Experiments!$R$2:$R$5000,"<>")=0,"",AVERAGEIFS(Experiments!$R$2:$R$5000,Experiments!$E$2:$E$5000,$A5)) -> 4.319 | I5: =IF(COUNTIFS(Experiments!$E$2:$E$5000,$A5,Experiments!$S$2:$S$5000,"<>")=0,"",AVERAGEIFS(Experiments!$S$2:$S$5000,Experiments!$E$2:$E$5000,$A5)) -> 31.686 | J5: =IF(COUNTIFS(Experiments!$E$2:$E$5000,$A5,Experiments!$AC$2:$AC$5000,"<>")=0,"",AVERAGEIFS(Experiments!$AC$2:$AC$5000,Experiments!$E$2:$E$5000,$A5)) -> 21.043 | K5: =IF(COUNTIFS(Experiments!$E$2:$E$5000,$A5,Experiments!$AB$2:$AB$5000,"<>")=0,"",AVERAGEIFS(Experiments!$AB$2:$AB$5000,Experiments!$E$2:$E$5000,$A5)) -> 10.643
A6: S2 | B6: Object NOT in scene ('give me the book') | C6: =COUNTIFS(Experiments!$E$2:$E$5000,$A6) -> 13 | D6: =COUNTIFS(Experiments!$E$2:$E$5000,$A6,Experiments!$Q$2:$Q$5000,"yes") -> 3 | E6: =COUNTIFS(Experiments!$E$2:$E$5000,$A6,Experiments!$Q$2:$Q$5000,"no") -> 0 | F6: =IF(D6+E6=0,"",D6/(D6+E6)) -> 1 | G6: =COUNTIFS(Experiments!$E$2:$E$5000,$A6,Experiments!$O$2:$O$5000,"yes") -> 0 | H6: =IF(COUNTIFS(Experiments!$E$2:$E$5000,$A6,Experiments!$R$2:$R$5000,"<>")=0,"",AVERAGEIFS(Experiments!$R$2:$R$5000,Experiments!$E$2:$E$5000,$A6)) | I6: =IF(COUNTIFS(Experiments!$E$2:$E$5000,$A6,Experiments!$S$2:$S$5000,"<>")=0,"",AVERAGEIFS(Experiments!$S$2:$S$5000,Experiments!$E$2:$E$5000,$A6)) | J6: =IF(COUNTIFS(Experiments!$E$2:$E$5000,$A6,Experiments!$AC$2:$AC$5000,"<>")=0,"",AVERAGEIFS(Experiments!$AC$2:$AC$5000,Experiments!$E$2:$E$5000,$A6)) | K6: =IF(COUNTIFS(Experiments!$E$2:$E$5000,$A6,Experiments!$AB$2:$AB$5000,"<>")=0,"",AVERAGEIFS(Experiments!$AB$2:$AB$5000,Experiments!$E$2:$E$5000,$A6))
A7: S3 | B7: One of a kind among others — ask for it | C7: =COUNTIFS(Experiments!$E$2:$E$5000,$A7) -> 14 | D7: =COUNTIFS(Experiments!$E$2:$E$5000,$A7,Experiments!$Q$2:$Q$5000,"yes") -> 13 | E7: =COUNTIFS(Experiments!$E$2:$E$5000,$A7,Experiments!$Q$2:$Q$5000,"no") -> 0 | F7: =IF(D7+E7=0,"",D7/(D7+E7)) -> 1 | G7: =COUNTIFS(Experiments!$E$2:$E$5000,$A7,Experiments!$O$2:$O$5000,"yes") -> 13 | H7: =IF(COUNTIFS(Experiments!$E$2:$E$5000,$A7,Experiments!$R$2:$R$5000,"<>")=0,"",AVERAGEIFS(Experiments!$R$2:$R$5000,Experiments!$E$2:$E$5000,$A7)) -> 3.8955 | I7: =IF(COUNTIFS(Experiments!$E$2:$E$5000,$A7,Experiments!$S$2:$S$5000,"<>")=0,"",AVERAGEIFS(Experiments!$S$2:$S$5000,Experiments!$E$2:$E$5000,$A7)) -> 41.264643 | J7: =IF(COUNTIFS(Experiments!$E$2:$E$5000,$A7,Experiments!$AC$2:$AC$5000,"<>")=0,"",AVERAGEIFS(Experiments!$AC$2:$AC$5000,Experiments!$E$2:$E$5000,$A7)) -> 20.617071 | K7: =IF(COUNTIFS(Experiments!$E$2:$E$5000,$A7,Experiments!$AB$2:$AB$5000,"<>")=0,"",AVERAGEIFS(Experiments!$AB$2:$AB$5000,Experiments!$E$2:$E$5000,$A7)) -> 20.647571
A8: S4 | B8: Two same kind — clarify by words (left/right/colour) | C8: =COUNTIFS(Experiments!$E$2:$E$5000,$A8) -> 13 | D8: =COUNTIFS(Experiments!$E$2:$E$5000,$A8,Experiments!$Q$2:$Q$5000,"yes") -> 13 | E8: =COUNTIFS(Experiments!$E$2:$E$5000,$A8,Experiments!$Q$2:$Q$5000,"no") -> 0 | F8: =IF(D8+E8=0,"",D8/(D8+E8)) -> 1 | G8: =COUNTIFS(Experiments!$E$2:$E$5000,$A8,Experiments!$O$2:$O$5000,"yes") -> 12 | H8: =IF(COUNTIFS(Experiments!$E$2:$E$5000,$A8,Experiments!$R$2:$R$5000,"<>")=0,"",AVERAGEIFS(Experiments!$R$2:$R$5000,Experiments!$E$2:$E$5000,$A8)) -> 24.494692 | I8: =IF(COUNTIFS(Experiments!$E$2:$E$5000,$A8,Experiments!$S$2:$S$5000,"<>")=0,"",AVERAGEIFS(Experiments!$S$2:$S$5000,Experiments!$E$2:$E$5000,$A8)) -> 64.567538 | J8: =IF(COUNTIFS(Experiments!$E$2:$E$5000,$A8,Experiments!$AC$2:$AC$5000,"<>")=0,"",AVERAGEIFS(Experiments!$AC$2:$AC$5000,Experiments!$E$2:$E$5000,$A8)) -> 43.084154 | K8: =IF(COUNTIFS(Experiments!$E$2:$E$5000,$A8,Experiments!$AB$2:$AB$5000,"<>")=0,"",AVERAGEIFS(Experiments!$AB$2:$AB$5000,Experiments!$E$2:$E$5000,$A8)) -> 21.483385
A9: S5 | B9: Two same kind — clarify by pointing | C9: =COUNTIFS(Experiments!$E$2:$E$5000,$A9) -> 11 | D9: =COUNTIFS(Experiments!$E$2:$E$5000,$A9,Experiments!$Q$2:$Q$5000,"yes") -> 11 | E9: =COUNTIFS(Experiments!$E$2:$E$5000,$A9,Experiments!$Q$2:$Q$5000,"no") -> 0 | F9: =IF(D9+E9=0,"",D9/(D9+E9)) -> 1 | G9: =COUNTIFS(Experiments!$E$2:$E$5000,$A9,Experiments!$O$2:$O$5000,"yes") -> 11 | H9: =IF(COUNTIFS(Experiments!$E$2:$E$5000,$A9,Experiments!$R$2:$R$5000,"<>")=0,"",AVERAGEIFS(Experiments!$R$2:$R$5000,Experiments!$E$2:$E$5000,$A9)) -> 23.086 | I9: =IF(COUNTIFS(Experiments!$E$2:$E$5000,$A9,Experiments!$S$2:$S$5000,"<>")=0,"",AVERAGEIFS(Experiments!$S$2:$S$5000,Experiments!$E$2:$E$5000,$A9)) -> 58.196636 | J9: =IF(COUNTIFS(Experiments!$E$2:$E$5000,$A9,Experiments!$AC$2:$AC$5000,"<>")=0,"",AVERAGEIFS(Experiments!$AC$2:$AC$5000,Experiments!$E$2:$E$5000,$A9)) -> 32.576818 | K9: =IF(COUNTIFS(Experiments!$E$2:$E$5000,$A9,Experiments!$AB$2:$AB$5000,"<>")=0,"",AVERAGEIFS(Experiments!$AB$2:$AB$5000,Experiments!$E$2:$E$5000,$A9)) -> 25.619818
A10: S6 | B10: Pointing only (with confirmation) | C10: =COUNTIFS(Experiments!$E$2:$E$5000,$A10) -> 12 | D10: =COUNTIFS(Experiments!$E$2:$E$5000,$A10,Experiments!$Q$2:$Q$5000,"yes") -> 12 | E10: =COUNTIFS(Experiments!$E$2:$E$5000,$A10,Experiments!$Q$2:$Q$5000,"no") -> 0 | F10: =IF(D10+E10=0,"",D10/(D10+E10)) -> 1 | G10: =COUNTIFS(Experiments!$E$2:$E$5000,$A10,Experiments!$O$2:$O$5000,"yes") -> 12 | H10: =IF(COUNTIFS(Experiments!$E$2:$E$5000,$A10,Experiments!$R$2:$R$5000,"<>")=0,"",AVERAGEIFS(Experiments!$R$2:$R$5000,Experiments!$E$2:$E$5000,$A10)) -> 10.940417 | I10: =IF(COUNTIFS(Experiments!$E$2:$E$5000,$A10,Experiments!$S$2:$S$5000,"<>")=0,"",AVERAGEIFS(Experiments!$S$2:$S$5000,Experiments!$E$2:$E$5000,$A10)) -> 52.521667 | J10: =IF(COUNTIFS(Experiments!$E$2:$E$5000,$A10,Experiments!$AC$2:$AC$5000,"<>")=0,"",AVERAGEIFS(Experiments!$AC$2:$AC$5000,Experiments!$E$2:$E$5000,$A10)) -> 19.764833 | K10: =IF(COUNTIFS(Experiments!$E$2:$E$5000,$A10,Experiments!$AB$2:$AB$5000,"<>")=0,"",AVERAGEIFS(Experiments!$AB$2:$AB$5000,Experiments!$E$2:$E$5000,$A10)) -> 32.756833
A11: S7 | B11: Moving without grasping | C11: =COUNTIFS(Experiments!$E$2:$E$5000,$A11) -> 11 | D11: =COUNTIFS(Experiments!$E$2:$E$5000,$A11,Experiments!$Q$2:$Q$5000,"yes") -> 3 | E11: =COUNTIFS(Experiments!$E$2:$E$5000,$A11,Experiments!$Q$2:$Q$5000,"no") -> 0 | F11: =IF(D11+E11=0,"",D11/(D11+E11)) -> 1 | G11: =COUNTIFS(Experiments!$E$2:$E$5000,$A11,Experiments!$O$2:$O$5000,"yes") -> 0 | H11: =IF(COUNTIFS(Experiments!$E$2:$E$5000,$A11,Experiments!$R$2:$R$5000,"<>")=0,"",AVERAGEIFS(Experiments!$R$2:$R$5000,Experiments!$E$2:$E$5000,$A11)) -> 8.6402727 | I11: =IF(COUNTIFS(Experiments!$E$2:$E$5000,$A11,Experiments!$S$2:$S$5000,"<>")=0,"",AVERAGEIFS(Experiments!$S$2:$S$5000,Experiments!$E$2:$E$5000,$A11)) | J11: =IF(COUNTIFS(Experiments!$E$2:$E$5000,$A11,Experiments!$AC$2:$AC$5000,"<>")=0,"",AVERAGEIFS(Experiments!$AC$2:$AC$5000,Experiments!$E$2:$E$5000,$A11)) | K11: =IF(COUNTIFS(Experiments!$E$2:$E$5000,$A11,Experiments!$AB$2:$AB$5000,"<>")=0,"",AVERAGEIFS(Experiments!$AB$2:$AB$5000,Experiments!$E$2:$E$5000,$A11))
A12: All | C12: =SUM(C5:C11) -> 88 | D12: =SUM(D5:D11) -> 58 | E12: =SUM(E5:E11) -> 0 | F12: =IF(D12+E12=0,"",D12/(D12+E12)) -> 1 | G12: =SUM(G5:G11) -> 49 | H12: =IF(COUNT(Experiments!$R$2:$R$5000)=0,"",AVERAGE(Experiments!$R$2:$R$5000)) -> 13.831629 | I12: =IF(COUNT(Experiments!$S$2:$S$5000)=0,"",AVERAGE(Experiments!$S$2:$S$5000)) -> 53.31749 | J12: =IF(COUNT(Experiments!$AC$2:$AC$5000)=0,"",AVERAGE(Experiments!$AC$2:$AC$5000)) -> 28.731353 | K12: =IF(COUNT(Experiments!$AB$2:$AB$5000)=0,"",AVERAGE(Experiments!$AB$2:$AB$5000)) -> 24.586137
A14: Trials per scenario and layout
A15: Scenario ID | B15: Layout A
A16: S1 | B16: =COUNTIFS(Experiments!$E$2:$E$5000,$A16,Experiments!$D$2:$D$5000,"Layout A") -> 6
A17: S2 | B17: =COUNTIFS(Experiments!$E$2:$E$5000,$A17,Experiments!$D$2:$D$5000,"Layout A") -> 5
A18: S3 | B18: =COUNTIFS(Experiments!$E$2:$E$5000,$A18,Experiments!$D$2:$D$5000,"Layout A") -> 7
A19: S4 | B19: =COUNTIFS(Experiments!$E$2:$E$5000,$A19,Experiments!$D$2:$D$5000,"Layout A") -> 7
A20: S5 | B20: =COUNTIFS(Experiments!$E$2:$E$5000,$A20,Experiments!$D$2:$D$5000,"Layout A") -> 6
A21: S6 | B21: =COUNTIFS(Experiments!$E$2:$E$5000,$A21,Experiments!$D$2:$D$5000,"Layout A") -> 5
A22: S7 | B22: =COUNTIFS(Experiments!$E$2:$E$5000,$A22,Experiments!$D$2:$D$5000,"Layout A") -> 5

Sheet Definitions
A1: Column / item | B1: Meaning
A2: Where the data comes from | B2: Every sheet is rebuilt from the trial folders (trial.json, timeline.json, meta.json) each time the window sends. Edit a trial in the MMHRI window (or its trial.json), not in these sheets — your edits here would be replaced. Sheets you add yourself are kept.
A3: Interaction Time (s) | B3: The experiment doc's definition: from the moment the command was GIVEN (you stopped saying it; for a pick started by pointing, the moment the object was chosen) until the arm STARTS MOVING. Includes speech recognition, understanding, any clarification ('which one?'), choosing the object and planning.
A4: Total Time (s) | B4: From the first command (or the pointing choice) to the end of the robot's cycle (back home).
A5: Started by | B5: voice = the task began with a spoken command; pointing/click = the object was chosen by pointing or a click before anything was said.
A6: End of your voice → transcript (s) | B6: The end-of-speech wait (0.5-0.8 s, to be sure you finished) plus speech recognition.
A7: You stopped speaking → command (s) | B7: The end of the operator's voice → the robot command for that sentence.
A8: Understanding: transcript → command (s) | B8: The accepted transcript that caused the command → the command.
A9: Understood by | B9: instant rule = the fixed phrase layer (about 0.01 s); language model = Claude (about 1 s).
A10: Command → object chosen, incl. clarification (s) | B10: The first command → the pipeline committing the object. Includes a clarification dialogue ('which one?') or the pointing, and handing the object's name to the pipeline.
A11: Object chosen → grasp candidates (s) | B11: The committed choice → grasp candidates published (capture, segmentation, the stored-grasp lookup, or GraspGen when nothing was stored).
A12: GraspGen in background? | B12: yes = GraspGen had already computed this object's grasps before the command (precompute); no = it ran after the command, and the operator waited for it.
... A26: Summary: success rate | B26: Full Task Success = yes divided by (yes + no); trials without a verdict are not counted.

Sheet _trials
A1: trial folder
A2: /home/deep/morty_ws/experiments/experiments_28_09_2026/trial_086_LA_S1
A3: /home/deep/morty_ws/experiments/experiments_28_09_2026/trial_087_LA_S2
A4: /home/deep/morty_ws/experiments/experiments_28_09_2026/trial_088_LA_S3
A5: /home/deep/morty_ws/experiments/experiments_28_09_2026/trial_089_LA_S4
A6: /home/deep/morty_ws/experiments/experiments_28_09_2026/trial_090_LA_S5
A7: /home/deep/morty_ws/experiments/experiments_28_09_2026/trial_091_LA_S6
A8: /home/deep/morty_ws/experiments/experiments_28_09_2026/trial_092_LA_S1
A9: /home/deep/morty_ws/experiments/experiments_28_09_2026/trial_093_LA_S2
A10: /home/deep/morty_ws/experiments/experiments_28_09_2026/trial_094_LA_S3
A11: /home/deep/morty_ws/experiments/experiments_28_09_2026/trial_095_LA_S3
A12: /home/deep/morty_ws/experiments/experiments_28_09_2026/trial_097_LA_S5
... A91: /home/deep/morty_ws/experiments/experiments_01_10_2026/trial_187_LA_S3
